Workbook

Sheet Orientações
A1: PLANILHA DE PONTUAÇÃO E PRONTIDÃO — APCN 2026
A2: Mestrado | Área 49 — Ciências Ambientais
A4: MODALIDADE | B4: Profissional | C4: Altere apenas este seletor se a proposta for acadêmica; o resumo ajusta automaticamente a exigência dos PTTs adicionais.
A6: FINALIDADE | B6: Organizar o corpo docente, classificar os artigos segundo a Área 49 e verificar a completude das produções de destaque e dos PTTs.
A7: JANELA TEMPORAL | B7: Para o Edital CAPES nº 20/2026, considerar 2021–2026: os cinco anos anteriores acrescidos do ano de submissão.
A8: ARTIGOS | B8: Registrar os artigos dos docentes permanentes com DOI. Periódicos estrangeiros: WoS e, complementarmente, Scopus. Periódicos brasileiros abaixo do percentil 50 ou não consolidados: usar as duas condições da Dimensions.
A9: REFERÊNCIA DO MESTRADO | B9: A média das produções em artigos deve alcançar índice mínimo esperado de 0,50. O resultado individual é diagnóstico; o requisito textual refere-se à média das produções do grupo.
A10: DESTAQUES | B10: Indicar duas produções de destaque por docente permanente, acompanhadas da Ficha de Impacto Real e de evidências.
A11: MESTRADO PROFISSIONAL | B11: Além dos indicadores gerais, indicar três PTTs adicionais por docente permanente, com Ficha de Impacto Real, link/anexo e justificativa de aderência.
A12: PTTs | B12: A APCN de Ciências Ambientais não fixa pontuação numérica prévia para cada tipologia. Os PTTs são avaliados por aderência, impacto, aplicabilidade, inovação e complexidade.
A13: MATERNIDADE | B13: Docentes que foram mães nos 24 meses anteriores à submissão são excluídas do cálculo geral de produção; a condição deve ser indicada claramente na proposta.
A14: CORPO DOCENTE | B14: Mínimo de 12 docentes permanentes; colaboradores até 30% do corpo docente total; externos no quadro permanente até 30%, com carta de cessão.
A15: DEDICAÇÃO | B15: Ao menos 50% dos docentes permanentes com contrato de 40h; todos com no mínimo 14h semanais no curso; média desejável de 15h.
A16: VÍNCULOS | B16: A Área 49 admite atuação como permanente em até dois PPGs, incluindo propostas novas. O Edital também impede cadastrar quem já atua em três programas/propostas.
A17: USO | B17: 1) Preencha “Lançamentos - Artigos”. 2) Preencha “Destaques e PTTs”. 3) Acompanhe as pendências no resumo e no checklist.
A18: LIMITAÇÃO | B18: Planilha de apoio baseada nos documentos oficiais vigentes em setembro de 2026.
A20: FONTES OFICIAIS ORGANIZADAS NA PASTA
A21: Documento orientador APCN — Ciências Ambientais 2026 | E21: =HYPERLINK("https://drive.google.com/file/d/1sPPe5quxj4cmBdZ1kJ_cUaX2jb0-3fwV/view?usp=drivesdk","Abrir arquivo na pasta") -> Abrir arquivo na pasta
A22: Ficha de avaliação — Ciências Ambientais 2025–2028 | E22: =HYPERLINK("https://drive.google.com/file/d/1nZ2Wg1-k6_pl-n21MEjwS4dYw9e7-AEU/view?usp=drivesdk","Abrir arquivo na pasta") -> Abrir arquivo na pasta
A23: Documento de Área — Ciências Ambientais 2025–2028 | E23: =HYPERLINK("https://drive.google.com/file/d/1v6Bm0-3GNPp-Qrp6tzjtcfZlH0ItC5hq/view?usp=drivesdk","Abrir arquivo na pasta") -> Abrir arquivo na pasta
A24: Anexo — Ficha de Impacto Real | E24: =HYPERLINK("https://drive.google.com/file/d/1yHDw_hEfQZtOsEV3U-ewKTrH9DGMT8Bh/view?usp=drivesdk","Abrir arquivo na pasta") -> Abrir arquivo na pasta
A25: Edital CAPES nº 20/2026 — APCN | E25: =HYPERLINK("https://drive.google.com/file/d/1Bzs3znyv-K_yff20DxvfyTZQe-Zg3qBK/view?usp=drivesdk","Abrir arquivo na pasta") -> Abrir arquivo na pasta
A26: Portaria CAPES nº 246/2026 — APCN | E26: =HYPERLINK("https://drive.google.com/file/d/1z_WwJI1RBFcgcNhSAU5JHqbzwa8aQbu_/view?usp=drivesdk","Abrir arquivo na pasta") -> Abrir arquivo na pasta
A27: Guia de submissão APCN 2026 | E27: =HYPERLINK("https://drive.google.com/file/d/1t-dJ_SNpGh7GKI96Z43gB6ZZ2AIc-UlC/view?usp=drivesdk","Abrir arquivo na pasta") -> Abrir arquivo na pasta
A28: Ofício nº 30/2026 — produções, Lattes e OpenAlex | E28: =HYPERLINK("https://drive.google.com/file/d/1Y4Y2L-Jl2SQZbTJorXAru3hC5GdFrGPE/view?usp=drivesdk","Abrir arquivo na pasta") -> Abrir arquivo na pasta

Sheet Estratos e PTTs
A1: CRITÉRIOS DE REFERÊNCIA — ÁREA 49
A2: Estrato | B2: WoS/Scopus: percentil | C2: Dimensions: maior % de artigos citados | D2: Dimensions: média de citações | E2: Índice por artigo
A3: E1 | B3: ≥ 87,5 | C3: ≥ 87,5 | D3: ≥ 2,00 | E3: 1
A4: E2 | B4: ≥ 75,0 | C4: ≥ 75,0 | D4: ≥ 1,50 | E4: 0.875
A5: E3 | B5: ≥ 62,5 | C5: ≥ 62,5 | D5: ≥ 1,00 | E5: 0.75
A6: E4 | B6: ≥ 50,0 | C6: ≥ 50,0 | D6: ≥ 0,75 | E6: 0.625
A7: E5 | B7: ≥ 37,5 | C7: ≥ 37,5 | D7: ≥ 0,50 | E7: 0.5
A8: E6 | B8: ≥ 25,0 | C8: ≥ 25,0 | D8: ≥ 0,25 | E8: 0.375
A9: E7 | B9: ≥ 12,5 | C9: ≥ 12,5 | D9: ≥ 0,125 | E9: 0.25
A10: E8 | B10: ≥ 0,01 | C10: ≥ 0,01 | D10: ≥ 0,01 | E10: 0.125
A11: Dimensions: aplicar simultaneamente as duas condições e usar o resultado de menor desempenho. Quando o periódico estiver em WoS e Scopus, utilizar o percentil mais favorável.
A13: 16 TIPOLOGIAS DE PRODUTOS TÉCNICOS E TECNOLÓGICOS (PTTs)
A14: Código | B14: Tipologia oficial | C14: Exemplos / escopo | D14: Dimensões avaliadas | E14: Tratamento na APCN
A15: PTT01 | B15: Produto bibliográfico | C15: Artigo em revista técnica ou de divulgação científica; livro ou série técnica | D15: Aderência, impacto, aplicabilidade, inovação e complexidade | E15: Sem pontos APCN pré-fixados; avaliação qualitativa
A16: PTT02 | B16: Ativos de Propriedade Intelectual | C16: Patente; desenho industrial; indicação geográfica; marca; topografia de circuito | D16: Aderência, impacto, aplicabilidade, inovação e complexidade | E16: Sem pontos APCN pré-fixados; avaliação qualitativa
A17: PTT03 | B17: Tecnologia Social | C17: Técnicas ou metodologias transformadoras desenvolvidas/aplicadas com a população | D17: Aderência, impacto, aplicabilidade, inovação e complexidade | E17: Sem pontos APCN pré-fixados; avaliação qualitativa
A18: PTT04 | B18: Produto de editoração | C18: Catálogo, coletânea, enciclopédia, revista, anais ou catálogo artístico organizado | D18: Aderência, impacto, aplicabilidade, inovação e complexidade | E18: Sem pontos APCN pré-fixados; avaliação qualitativa
A19: PTT05 | B19: Material didático ou educacional | C19: Material finalizado para processos de ensino, formação ou educação | D19: Aderência, impacto, aplicabilidade, inovação e complexidade | E19: Sem pontos APCN pré-fixados; avaliação qualitativa
A20: PTT06 | B20: Software/Aplicativo | C20: Programa de computador ou aplicativo | D20: Aderência, impacto, aplicabilidade, inovação e complexidade | E20: Sem pontos APCN pré-fixados; avaliação qualitativa
A21: PTT07 | B21: Norma ou Marco regulatório | C21: Norma, anteprojeto, estudo de regulamentação, audiência pública, peça técnica | D21: Aderência, impacto, aplicabilidade, inovação e complexidade | E21: Sem pontos APCN pré-fixados; avaliação qualitativa
A22: PTT08 | B22: Relatório técnico conclusivo | C22: Relatório, processo de gestão, pesquisa de mercado, simulação, modelo ou parecer técnico | D22: Aderência, impacto, aplicabilidade, inovação e complexidade | E22: Sem pontos APCN pré-fixados; avaliação qualitativa
A23: PTT09 | B23: Manual/Protocolo | C23: Protocolo tecnológico, POP ou manual de operação técnica | D23: Aderência, impacto, aplicabilidade, inovação e complexidade | E23: Sem pontos APCN pré-fixados; avaliação qualitativa
A24: PTT10 | B24: Acervo | C24: Curadoria de mostras, exposições, coleções biológicas ou acervos produzidos | D24: Aderência, impacto, aplicabilidade, inovação e complexidade | E24: Sem pontos APCN pré-fixados; avaliação qualitativa
A25: PTT11 | B25: Cultivar | C25: Cultivar desenvolvida ou registrada | D25: Aderência, impacto, aplicabilidade, inovação e complexidade | E25: Sem pontos APCN pré-fixados; avaliação qualitativa
... A30: PTT16 | B30: Processo/Tecnologia e Produto/Material não patenteável | C30: Processo, tecnologia, produto ou material sem proteção patentária | D30: Aderência, impacto, aplicabilidade, inovação e complexidade | E30: Sem pontos APCN pré-fixados; avaliação qualitativa

Sheet Resumo por docente
A1: RESUMO E CADASTRO DO CORPO DOCENTE — MESTRADO
A2: Modalidade | B2: ='Orientações'!B4 -> Profissional | D2: DP cadastrados | E2: =COUNTA($A$8:$A$57) -> 17 | G2: Mínimo exigido | H2: 12 | J2: Situação do quantitativo | K2: =IF(E2>=H2,"ATENDE","FALTAM "&(H2-E2)) -> ATENDE
A3: Média dos artigos do grupo | B3: =IFERROR(SUMIFS($H$8:$H$57,$A$8:$A$57,"<>",$C$8:$C$57,"<>sim")/SUMIFS($G$8:$G$57,$A$8:$A$57,"<>",$C$8:$C$57,"<>sim"),0) -> 0.71428571 | D3: Referência do mestrado | E3: 0.5 | G3: Situação da média | H3: =IF(B3>=E3,"ATENDE","ABAIXO DE 0,50") -> ATENDE | J3: DP 40h | K3: =IFERROR(COUNTIFS($A$8:$A$57,"<>",$D$8:$D$57,"sim")/COUNTA($A$8:$A$57),0) -> 1
A4: Carga mínima de 14h | B4: =IF(COUNTA($A$8:$A$57)=0,"AGUARDANDO",IF(COUNTIFS($A$8:$A$57,"<>",$E$8:$E$57,">=14")=COUNTA($A$8:$A$57),"ATENDE","REVISAR")) -> REVISAR | D4: Média de horas | E4: =IFERROR(AVERAGEIF($A$8:$A$57,"<>",$E$8:$E$57),0) -> 14 | G4: Maior nº de vínculos DP | H4: =IFERROR(MAX($F$8:$F$57),0) -> 1 | J4: Situação dedicação | K4: =IF(COUNTA($A$8:$A$57)=0,"AGUARDANDO",IF(AND(B4="ATENDE",E4>=15,H4<=2,K3>=50%),"ATENDE","REVISAR")) -> REVISAR
A5: DP com indicações completas | B5: =COUNTIF($M$8:$M$57,"OK") -> 1 | D5: Total de DP | E5: =COUNTA($A$8:$A$57) -> 17 | G5: Situação das indicações | H5: =IF(E5=0,"AGUARDANDO",IF(B5=E5,"ATENDE","PENDENTE")) -> PENDENTE | J5: Regra | K5: =IF('Orientações'!B4="Profissional","2 destaques + 3 PTTs/DP","2 destaques/DP") -> 2 destaques + 3 PTTs/DP
A6: Preencha as colunas amarelas. As demais são calculadas automaticamente.
A7: Docente permanente | B7: Linha de pesquisa/atuação | C7: Maternidade nos 24 meses? | D7: Vinculo 40h | E7: Horas semanais no curso | F7: Nº de vínculos como DP (inclui proposta) | G7: Artigos válidos | H7: Soma dos índices | I7: Média dos artigos | J7: Diagnóstico da produção | K7: Destaques completos | L7: PTTs adicionais completos | M7: Indicações exigidas | N7: Situação geral | O7: Observações
A8: ANDERSON SALDANHA BUENO | B8: Biodiversidade, Saúde Ambiental e Conservação | C8: não | D8: sim | G8: =IF($A8="","",COUNTIFS('Lançamentos - Artigos'!$A$2:$A$506,$A8,'Lançamentos - Artigos'!$L$2:$L$506,">0")) -> 0 | H8: =IF($A8="","",SUMIFS('Lançamentos - Artigos'!$L$2:$L$506,'Lançamentos - Artigos'!$A$2:$A$506,$A8)) -> 0 | I8: =IF(OR($A8="",G8=0),"",H8/G8) | J8: =IF($A8="","",IF(LOWER($C8)="sim","EXCLUÍDA DO CÁLCULO GERAL",IF(G8=0,"SEM ARTIGO VÁLIDO",IF(I8>=0.5,"REFERÊNCIA ATENDIDA","ABAIXO DE 0,50")))) -> SEM ARTIGO VÁLIDO | K8: =IF($A8="","",COUNTIFS('Destaques e PTTs'!$A$2:$A$501,$A8,'Destaques e PTTs'!$C$2:$C$501,"Destaque*",'Destaques e PTTs'!$W$2:$W$501,"OK")) -> 0 | L8: =IF($A8="","",COUNTIFS('Destaques e PTTs'!$A$2:$A$501,$A8,'Destaques e PTTs'!$C$2:$C$501,"PTT adicional*",'Destaques e PTTs'!$W$2:$W$501,"OK")) -> 0 | M8: =IF($A8="","",IF('Orientações'!$B$4="Profissional",IF(AND(K8=2,L8=3),"OK",IF(OR(K8>2,L8>3),"EXCEDE","PENDENTE")),IF(K8=2,"OK",IF(K8>2,"EXCEDE","PENDENTE")))) -> PENDENTE | N8: =IF($A8="","",IF(OR(LOWER($D8)<>"sim",$E8<14,$F8>2,$M8<>"OK",AND(LOWER($C8)<>"sim",G8=0)),"REVISAR","OK")) -> REVISAR
A9: CARLOS RODRIGO LEHN | B9: Biodiversidade, Saúde Ambiental e Conservação | C9: não | D9: sim | G9: =IF($A9="","",COUNTIFS('Lançamentos - Artigos'!$A$2:$A$506,$A9,'Lançamentos - Artigos'!$L$2:$L$506,">0")) -> 0 | H9: =IF($A9="","",SUMIFS('Lançamentos - Artigos'!$L$2:$L$506,'Lançamentos - Artigos'!$A$2:$A$506,$A9)) -> 0 | I9: =IF(OR($A9="",G9=0),"",H9/G9) | J9: =IF($A9="","",IF(LOWER($C9)="sim","EXCLUÍDA DO CÁLCULO GERAL",IF(G9=0,"SEM ARTIGO VÁLIDO",IF(I9>=0.5,"REFERÊNCIA ATENDIDA","ABAIXO DE 0,50")))) -> SEM ARTIGO VÁLIDO | K9: =IF($A9="","",COUNTIFS('Destaques e PTTs'!$A$2:$A$501,$A9,'Destaques e PTTs'!$C$2:$C$501,"Destaque*",'Destaques e PTTs'!$W$2:$W$501,"OK")) -> 0 | L9: =IF($A9="","",COUNTIFS('Destaques e PTTs'!$A$2:$A$501,$A9,'Destaques e PTTs'!$C$2:$C$501,"PTT adicional*",'Destaques e PTTs'!$W$2:$W$501,"OK")) -> 0 | M9: =IF($A9="","",IF('Orientações'!$B$4="Profissional",IF(AND(K9=2,L9=3),"OK",IF(OR(K9>2,L9>3),"EXCEDE","PENDENTE")),IF(K9=2,"OK",IF(K9>2,"EXCEDE","PENDENTE")))) -> PENDENTE | N9: =IF($A9="","",IF(OR(LOWER($D9)<>"sim",$E9<14,$F9>2,$M9<>"OK",AND(LOWER($C9)<>"sim",G9=0)),"REVISAR","OK")) -> REVISAR
A10: CAROLINE LEUCHTENBERGER | B10: Biodiversidade, Saúde Ambiental e Conservação | C10: não | D10: sim | G10: =IF($A10="","",COUNTIFS('Lançamentos - Artigos'!$A$2:$A$506,$A10,'Lançamentos - Artigos'!$L$2:$L$506,">0")) -> 0 | H10: =IF($A10="","",SUMIFS('Lançamentos - Artigos'!$L$2:$L$506,'Lançamentos - Artigos'!$A$2:$A$506,$A10)) -> 0 | I10: =IF(OR($A10="",G10=0),"",H10/G10) | J10: =IF($A10="","",IF(LOWER($C10)="sim","EXCLUÍDA DO CÁLCULO GERAL",IF(G10=0,"SEM ARTIGO VÁLIDO",IF(I10>=0.5,"REFERÊNCIA ATENDIDA","ABAIXO DE 0,50")))) -> SEM ARTIGO VÁLIDO | K10: =IF($A10="","",COUNTIFS('Destaques e PTTs'!$A$2:$A$501,$A10,'Destaques e PTTs'!$C$2:$C$501,"Destaque*",'Destaques e PTTs'!$W$2:$W$501,"OK")) -> 0 | L10: =IF($A10="","",COUNTIFS('Destaques e PTTs'!$A$2:$A$501,$A10,'Destaques e PTTs'!$C$2:$C$501,"PTT adicional*",'Destaques e PTTs'!$W$2:$W$501,"OK")) -> 0 | M10: =IF($A10="","",IF('Orientações'!$B$4="Profissional",IF(AND(K10=2,L10=3),"OK",IF(OR(K10>2,L10>3),"EXCEDE","PENDENTE")),IF(K10=2,"OK",IF(K10>2,"EXCEDE","PENDENTE")))) -> PENDENTE | N10: =IF($A10="","",IF(OR(LOWER($D10)<>"sim",$E10<14,$F10>2,$M10<>"OK",AND(LOWER($C10)<>"sim",G10=0)),"REVISAR","OK")) -> REVISAR
A11: EMANUELE JUNGES | B11: Inovação, Biotecnologia e Sustentabilidade Produtiva | C11: não | D11: sim | E11: 14 | F11: 0 | G11: =IF($A11="","",COUNTIFS('Lançamentos - Artigos'!$A$2:$A$506,$A11,'Lançamentos - Artigos'!$L$2:$L$506,">0")) -> 0 | H11: =IF($A11="","",SUMIFS('Lançamentos - Artigos'!$L$2:$L$506,'Lançamentos - Artigos'!$A$2:$A$506,$A11)) -> 0 | I11: =IF(OR($A11="",G11=0),"",H11/G11) | J11: =IF($A11="","",IF(LOWER($C11)="sim","EXCLUÍDA DO CÁLCULO GERAL",IF(G11=0,"SEM ARTIGO VÁLIDO",IF(I11>=0.5,"REFERÊNCIA ATENDIDA","ABAIXO DE 0,50")))) -> SEM ARTIGO VÁLIDO | K11: =IF($A11="","",COUNTIFS('Destaques e PTTs'!$A$2:$A$501,$A11,'Destaques e PTTs'!$C$2:$C$501,"Destaque*",'Destaques e PTTs'!$W$2:$W$501,"OK")) -> 0 | L11: =IF($A11="","",COUNTIFS('Destaques e PTTs'!$A$2:$A$501,$A11,'Destaques e PTTs'!$C$2:$C$501,"PTT adicional*",'Destaques e PTTs'!$W$2:$W$501,"OK")) -> 0 | M11: =IF($A11="","",IF('Orientações'!$B$4="Profissional",IF(AND(K11=2,L11=3),"OK",IF(OR(K11>2,L11>3),"EXCEDE","PENDENTE")),IF(K11=2,"OK",IF(K11>2,"EXCEDE","PENDENTE")))) -> PENDENTE | N11: =IF($A11="","",IF(OR(LOWER($D11)<>"sim",$E11<14,$F11>2,$M11<>"OK",AND(LOWER($C11)<>"sim",G11=0)),"REVISAR","OK")) -> REVISAR
A12: EVERTON LUTZ | D12: sim | G12: =IF($A12="","",COUNTIFS('Lançamentos - Artigos'!$A$2:$A$506,$A12,'Lançamentos - Artigos'!$L$2:$L$506,">0")) -> 0 | H12: =IF($A12="","",SUMIFS('Lançamentos - Artigos'!$L$2:$L$506,'Lançamentos - Artigos'!$A$2:$A$506,$A12)) -> 0 | I12: =IF(OR($A12="",G12=0),"",H12/G12) | J12: =IF($A12="","",IF(LOWER($C12)="sim","EXCLUÍDA DO CÁLCULO GERAL",IF(G12=0,"SEM ARTIGO VÁLIDO",IF(I12>=0.5,"REFERÊNCIA ATENDIDA","ABAIXO DE 0,50")))) -> SEM ARTIGO VÁLIDO | K12: =IF($A12="","",COUNTIFS('Destaques e PTTs'!$A$2:$A$501,$A12,'Destaques e PTTs'!$C$2:$C$501,"Destaque*",'Destaques e PTTs'!$W$2:$W$501,"OK")) -> 0 | L12: =IF($A12="","",COUNTIFS('Destaques e PTTs'!$A$2:$A$501,$A12,'Destaques e PTTs'!$C$2:$C$501,"PTT adicional*",'Destaques e PTTs'!$W$2:$W$501,"OK")) -> 0 | M12: =IF($A12="","",IF('Orientações'!$B$4="Profissional",IF(AND(K12=2,L12=3),"OK",IF(OR(K12>2,L12>3),"EXCEDE","PENDENTE")),IF(K12=2,"OK",IF(K12>2,"EXCEDE","PENDENTE")))) -> PENDENTE | N12: =IF($A12="","",IF(OR(LOWER($D12)<>"sim",$E12<14,$F12>2,$M12<>"OK",AND(LOWER($C12)<>"sim",G12=0)),"REVISAR","OK")) -> REVISAR
A13: FELIPE KETZER | B13: Inovação, Biotecnologia e Sustentabilidade Produtiva | C13: não | D13: sim | E13: 14 | F13: 1 | G13: =IF($A13="","",COUNTIFS('Lançamentos - Artigos'!$A$2:$A$506,$A13,'Lançamentos - Artigos'!$L$2:$L$506,">0")) -> 0 | H13: =IF($A13="","",SUMIFS('Lançamentos - Artigos'!$L$2:$L$506,'Lançamentos - Artigos'!$A$2:$A$506,$A13)) -> 0 | I13: =IF(OR($A13="",G13=0),"",H13/G13) | J13: =IF($A13="","",IF(LOWER($C13)="sim","EXCLUÍDA DO CÁLCULO GERAL",IF(G13=0,"SEM ARTIGO VÁLIDO",IF(I13>=0.5,"REFERÊNCIA ATENDIDA","ABAIXO DE 0,50")))) -> SEM ARTIGO VÁLIDO | K13: =IF($A13="","",COUNTIFS('Destaques e PTTs'!$A$2:$A$501,$A13,'Destaques e PTTs'!$C$2:$C$501,"Destaque*",'Destaques e PTTs'!$W$2:$W$501,"OK")) -> 0 | L13: =IF($A13="","",COUNTIFS('Destaques e PTTs'!$A$2:$A$501,$A13,'Destaques e PTTs'!$C$2:$C$501,"PTT adicional*",'Destaques e PTTs'!$W$2:$W$501,"OK")) -> 0 | M13: =IF($A13="","",IF('Orientações'!$B$4="Profissional",IF(AND(K13=2,L13=3),"OK",IF(OR(K13>2,L13>3),"EXCEDE","PENDENTE")),IF(K13=2,"OK",IF(K13>2,"EXCEDE","PENDENTE")))) -> PENDENTE | N13: =IF($A13="","",IF(OR(LOWER($D13)<>"sim",$E13<14,$F13>2,$M13<>"OK",AND(LOWER($C13)<>"sim",G13=0)),"REVISAR","OK")) -> REVISAR
A14: GERSON AZULIM MULLER | B14: Biodiversidade, Saúde Ambiental e Conservação | C14: não | D14: sim | E14: 14 | F14: 1 | G14: =IF($A14="","",COUNTIFS('Lançamentos - Artigos'!$A$2:$A$506,$A14,'Lançamentos - Artigos'!$L$2:$L$506,">0")) -> 0 | H14: =IF($A14="","",SUMIFS('Lançamentos - Artigos'!$L$2:$L$506,'Lançamentos - Artigos'!$A$2:$A$506,$A14)) -> 0 | I14: =IF(OR($A14="",G14=0),"",H14/G14) | J14: =IF($A14="","",IF(LOWER($C14)="sim","EXCLUÍDA DO CÁLCULO GERAL",IF(G14=0,"SEM ARTIGO VÁLIDO",IF(I14>=0.5,"REFERÊNCIA ATENDIDA","ABAIXO DE 0,50")))) -> SEM ARTIGO VÁLIDO | K14: =IF($A14="","",COUNTIFS('Destaques e PTTs'!$A$2:$A$501,$A14,'Destaques e PTTs'!$C$2:$C$501,"Destaque*",'Destaques e PTTs'!$W$2:$W$501,"OK")) -> 0 | L14: =IF($A14="","",COUNTIFS('Destaques e PTTs'!$A$2:$A$501,$A14,'Destaques e PTTs'!$C$2:$C$501,"PTT adicional*",'Destaques e PTTs'!$W$2:$W$501,"OK")) -> 0 | M14: =IF($A14="","",IF('Orientações'!$B$4="Profissional",IF(AND(K14=2,L14=3),"OK",IF(OR(K14>2,L14>3),"EXCEDE","PENDENTE")),IF(K14=2,"OK",IF(K14>2,"EXCEDE","PENDENTE")))) -> PENDENTE | N14: =IF($A14="","",IF(OR(LOWER($D14)<>"sim",$E14<14,$F14>2,$M14<>"OK",AND(LOWER($C14)<>"sim",G14=0)),"REVISAR","OK")) -> REVISAR
A15: GERUZA LEAL MELO | B15: Biodiversidade, Saúde Ambiental e Conservação | C15: não | D15: sim | E15: 14 | F15: 1 | G15: =IF($A15="","",COUNTIFS('Lançamentos - Artigos'!$A$2:$A$506,$A15,'Lançamentos - Artigos'!$L$2:$L$506,">0")) -> 0 | H15: =IF($A15="","",SUMIFS('Lançamentos - Artigos'!$L$2:$L$506,'Lançamentos - Artigos'!$A$2:$A$506,$A15)) -> 0 | I15: =IF(OR($A15="",G15=0),"",H15/G15) | J15: =IF($A15="","",IF(LOWER($C15)="sim","EXCLUÍDA DO CÁLCULO GERAL",IF(G15=0,"SEM ARTIGO VÁLIDO",IF(I15>=0.5,"REFERÊNCIA ATENDIDA","ABAIXO DE 0,50")))) -> SEM ARTIGO VÁLIDO | K15: =IF($A15="","",COUNTIFS('Destaques e PTTs'!$A$2:$A$501,$A15,'Destaques e PTTs'!$C$2:$C$501,"Destaque*",'Destaques e PTTs'!$W$2:$W$501,"OK")) -> 0 | L15: =IF($A15="","",COUNTIFS('Destaques e PTTs'!$A$2:$A$501,$A15,'Destaques e PTTs'!$C$2:$C$501,"PTT adicional*",'Destaques e PTTs'!$W$2:$W$501,"OK")) -> 0 | M15: =IF($A15="","",IF('Orientações'!$B$4="Profissional",IF(AND(K15=2,L15=3),"OK",IF(OR(K15>2,L15>3),"EXCEDE","PENDENTE")),IF(K15=2,"OK",IF(K15>2,"EXCEDE","PENDENTE")))) -> PENDENTE | N15: =IF($A15="","",IF(OR(LOWER($D15)<>"sim",$E15<14,$F15>2,$M15<>"OK",AND(LOWER($C15)<>"sim",G15=0)),"REVISAR","OK")) -> REVISAR
A16: JONAS SPONCHIADO | B16: Biodiversidade, Saúde Ambiental e Conservação | C16: não | D16: sim | E16: 14 | F16: 1 | G16: =IF($A16="","",COUNTIFS('Lançamentos - Artigos'!$A$2:$A$506,$A16,'Lançamentos - Artigos'!$L$2:$L$506,">0")) -> 0 | H16: =IF($A16="","",SUMIFS('Lançamentos - Artigos'!$L$2:$L$506,'Lançamentos - Artigos'!$A$2:$A$506,$A16)) -> 0 | I16: =IF(OR($A16="",G16=0),"",H16/G16) | J16: =IF($A16="","",IF(LOWER($C16)="sim","EXCLUÍDA DO CÁLCULO GERAL",IF(G16=0,"SEM ARTIGO VÁLIDO",IF(I16>=0.5,"REFERÊNCIA ATENDIDA","ABAIXO DE 0,50")))) -> SEM ARTIGO VÁLIDO | K16: =IF($A16="","",COUNTIFS('Destaques e PTTs'!$A$2:$A$501,$A16,'Destaques e PTTs'!$C$2:$C$501,"Destaque*",'Destaques e PTTs'!$W$2:$W$501,"OK")) -> 0 | L16: =IF($A16="","",COUNTIFS('Destaques e PTTs'!$A$2:$A$501,$A16,'Destaques e PTTs'!$C$2:$C$501,"PTT adicional*",'Destaques e PTTs'!$W$2:$W$501,"OK")) -> 0 | M16: =IF($A16="","",IF('Orientações'!$B$4="Profissional",IF(AND(K16=2,L16=3),"OK",IF(OR(K16>2,L16>3),"EXCEDE","PENDENTE")),IF(K16=2,"OK",IF(K16>2,"EXCEDE","PENDENTE")))) -> PENDENTE | N16: =IF($A16="","",IF(OR(LOWER($D16)<>"sim",$E16<14,$F16>2,$M16<>"OK",AND(LOWER($C16)<>"sim",G16=0)),"REVISAR","OK")) -> REVISAR
A17: LESSANDRO DE CONTI | D17: sim | G17: =IF($A17="","",COUNTIFS('Lançamentos - Artigos'!$A$2:$A$506,$A17,'Lançamentos - Artigos'!$L$2:$L$506,">0")) -> 0 | H17: =IF($A17="","",SUMIFS('Lançamentos - Artigos'!$L$2:$L$506,'Lançamentos - Artigos'!$A$2:$A$506,$A17)) -> 0 | I17: =IF(OR($A17="",G17=0),"",H17/G17) | J17: =IF($A17="","",IF(LOWER($C17)="sim","EXCLUÍDA DO CÁLCULO GERAL",IF(G17=0,"SEM ARTIGO VÁLIDO",IF(I17>=0.5,"REFERÊNCIA ATENDIDA","ABAIXO DE 0,50")))) -> SEM ARTIGO VÁLIDO | K17: =IF($A17="","",COUNTIFS('Destaques e PTTs'!$A$2:$A$501,$A17,'Destaques e PTTs'!$C$2:$C$501,"Destaque*",'Destaques e PTTs'!$W$2:$W$501,"OK")) -> 0 | L17: =IF($A17="","",COUNTIFS('Destaques e PTTs'!$A$2:$A$501,$A17,'Destaques e PTTs'!$C$2:$C$501,"PTT adicional*",'Destaques e PTTs'!$W$2:$W$501,"OK")) -> 0 | M17: =IF($A17="","",IF('Orientações'!$B$4="Profissional",IF(AND(K17=2,L17=3),"OK",IF(OR(K17>2,L17>3),"EXCEDE","PENDENTE")),IF(K17=2,"OK",IF(K17>2,"EXCEDE","PENDENTE")))) -> PENDENTE | N17: =IF($A17="","",IF(OR(LOWER($D17)<>"sim",$E17<14,$F17>2,$M17<>"OK",AND(LOWER($C17)<>"sim",G17=0)),"REVISAR","OK")) -> REVISAR
A18: LETICIA TREVISAN GRESSLER | D18: sim | G18: =IF($A18="","",COUNTIFS('Lançamentos - Artigos'!$A$2:$A$506,$A18,'Lançamentos - Artigos'!$L$2:$L$506,">0")) -> 0 | H18: =IF($A18="","",SUMIFS('Lançamentos - Artigos'!$L$2:$L$506,'Lançamentos - Artigos'!$A$2:$A$506,$A18)) -> 0 | I18: =IF(OR($A18="",G18=0),"",H18/G18) | J18: =IF($A18="","",IF(LOWER($C18)="sim","EXCLUÍDA DO CÁLCULO GERAL",IF(G18=0,"SEM ARTIGO VÁLIDO",IF(I18>=0.5,"REFERÊNCIA ATENDIDA","ABAIXO DE 0,50")))) -> SEM ARTIGO VÁLIDO | K18: =IF($A18="","",COUNTIFS('Destaques e PTTs'!$A$2:$A$501,$A18,'Destaques e PTTs'!$C$2:$C$501,"Destaque*",'Destaques e PTTs'!$W$2:$W$501,"OK")) -> 0 | L18: =IF($A18="","",COUNTIFS('Destaques e PTTs'!$A$2:$A$501,$A18,'Destaques e PTTs'!$C$2:$C$501,"PTT adicional*",'Destaques e PTTs'!$W$2:$W$501,"OK")) -> 0 | M18: =IF($A18="","",IF('Orientações'!$B$4="Profissional",IF(AND(K18=2,L18=3),"OK",IF(OR(K18>2,L18>3),"EXCEDE","PENDENTE")),IF(K18=2,"OK",IF(K18>2,"EXCEDE","PENDENTE")))) -> PENDENTE | N18: =IF($A18="","",IF(OR(LOWER($D18)<>"sim",$E18<14,$F18>2,$M18<>"OK",AND(LOWER($C18)<>"sim",G18=0)),"REVISAR","OK")) -> REVISAR
A19: MICAELA GUIDOTTI TAKEUCHI | B19: Inovação, Biotecnologia e Sustentabilidade Produtiva | C19: não | D19: sim | E19: 14 | F19: 1 | H19: =IF($A19="","",SUMIFS('Lançamentos - Artigos'!$L$2:$L$506,'Lançamentos - Artigos'!$A$2:$A$506,$A19)) -> 0 | I19: =IF(OR($A19="",G19=0),"",H19/G19) | J19: =IF($A19="","",IF(LOWER($C19)="sim","EXCLUÍDA DO CÁLCULO GERAL",IF(G19=0,"SEM ARTIGO VÁLIDO",IF(I19>=0.5,"REFERÊNCIA ATENDIDA","ABAIXO DE 0,50")))) -> SEM ARTIGO VÁLIDO | K19: =IF($A19="","",COUNTIFS('Destaques e PTTs'!$A$2:$A$501,$A19,'Destaques e PTTs'!$C$2:$C$501,"Destaque*",'Destaques e PTTs'!$W$2:$W$501,"OK")) -> 0 | L19: =IF($A19="","",COUNTIFS('Destaques e PTTs'!$A$2:$A$501,$A19,'Destaques e PTTs'!$C$2:$C$501,"PTT adicional*",'Destaques e PTTs'!$W$2:$W$501,"OK")) -> 0 | M19: =IF($A19="","",IF('Orientações'!$B$4="Profissional",IF(AND(K19=2,L19=3),"OK",IF(OR(K19>2,L19>3),"EXCEDE","PENDENTE")),IF(K19=2,"OK",IF(K19>2,"EXCEDE","PENDENTE")))) -> PENDENTE | N19: =IF($A19="","",IF(OR(LOWER($D19)<>"sim",$E19<14,$F19>2,$M19<>"OK",AND(LOWER($C19)<>"sim",G19=0)),"REVISAR","OK")) -> REVISAR
A20: RANGEL FERNANDES PACHECO | B20: Inovação, Biotecnologia e Sustentabilidade Produtiva | C20: não | D20: sim | E20: 14 | F20: 1 | G20: =IF($A20="","",COUNTIFS('Lançamentos - Artigos'!$A$2:$A$506,$A20,'Lançamentos - Artigos'!$L$2:$L$506,">0")) -> 7 | H20: =IF($A20="","",SUMIFS('Lançamentos - Artigos'!$L$2:$L$506,'Lançamentos - Artigos'!$A$2:$A$506,$A20)) -> 5 | I20: =IF(OR($A20="",G20=0),"",H20/G20) -> 0.71428571 | J20: =IF($A20="","",IF(LOWER($C20)="sim","EXCLUÍDA DO CÁLCULO GERAL",IF(G20=0,"SEM ARTIGO VÁLIDO",IF(I20>=0.5,"REFERÊNCIA ATENDIDA","ABAIXO DE 0,50")))) -> REFERÊNCIA ATENDIDA | K20: =IF($A20="","",COUNTIFS('Destaques e PTTs'!$A$2:$A$501,$A20,'Destaques e PTTs'!$C$2:$C$501,"Destaque*",'Destaques e PTTs'!$W$2:$W$501,"OK")) -> 2 | L20: =IF($A20="","",COUNTIFS('Destaques e PTTs'!$A$2:$A$501,$A20,'Destaques e PTTs'!$C$2:$C$501,"PTT adicional*",'Destaques e PTTs'!$W$2:$W$501,"OK")) -> 3 | M20: =IF($A20="","",IF('Orientações'!$B$4="Profissional",IF(AND(K20=2,L20=3),"OK",IF(OR(K20>2,L20>3),"EXCEDE","PENDENTE")),IF(K20=2,"OK",IF(K20>2,"EXCEDE","PENDENTE")))) -> OK | N20: =IF($A20="","",IF(OR(LOWER($D20)<>"sim",$E20<14,$F20>2,$M20<>"OK",AND(LOWER($C20)<>"sim",G20=0)),"REVISAR","OK")) -> OK
A21: TATIANA TOZZI MARTINS SOUZA RODRIGUES | D21: sim | G21: =IF($A21="","",COUNTIFS('Lançamentos - Artigos'!$A$2:$A$506,$A21,'Lançamentos - Artigos'!$L$2:$L$506,">0")) -> 0 | H21: =IF($A21="","",SUMIFS('Lançamentos - Artigos'!$L$2:$L$506,'Lançamentos - Artigos'!$A$2:$A$506,$A21)) -> 0 | I21: =IF(OR($A21="",G21=0),"",H21/G21) | J21: =IF($A21="","",IF(LOWER($C21)="sim","EXCLUÍDA DO CÁLCULO GERAL",IF(G21=0,"SEM ARTIGO VÁLIDO",IF(I21>=0.5,"REFERÊNCIA ATENDIDA","ABAIXO DE 0,50")))) -> SEM ARTIGO VÁLIDO | K21: =IF($A21="","",COUNTIFS('Destaques e PTTs'!$A$2:$A$501,$A21,'Destaques e PTTs'!$C$2:$C$501,"Destaque*",'Destaques e PTTs'!$W$2:$W$501,"OK")) -> 0 | L21: =IF($A21="","",COUNTIFS('Destaques e PTTs'!$A$2:$A$501,$A21,'Destaques e PTTs'!$C$2:$C$501,"PTT adicional*",'Destaques e PTTs'!$W$2:$W$501,"OK")) -> 0 | M21: =IF($A21="","",IF('Orientações'!$B$4="Profissional",IF(AND(K21=2,L21=3),"OK",IF(OR(K21>2,L21>3),"EXCEDE","PENDENTE")),IF(K21=2,"OK",IF(K21>2,"EXCEDE","PENDENTE")))) -> PENDENTE | N21: =IF($A21="","",IF(OR(LOWER($D21)<>"sim",$E21<14,$F21>2,$M21<>"OK",AND(LOWER($C21)<>"sim",G21=0)),"REVISAR","OK")) -> REVISAR
A22: Kátia Maria Cardinal | B22: Inovação, Biotecnologia e Sustentabilidade Produtiva | C22: não | D22: sim | E22: 14 | F22: 1 | G22: 0 | H22: =IF($A22="","",SUMIFS('Lançamentos - Artigos'!$L$2:$L$506,'Lançamentos - Artigos'!$A$2:$A$506,$A22)) -> 0 | I22: =IF(OR($A22="",G22=0),"",H22/G22) | J22: =IF($A22="","",IF(LOWER($C22)="sim","EXCLUÍDA DO CÁLCULO GERAL",IF(G22=0,"SEM ARTIGO VÁLIDO",IF(I22>=0.5,"REFERÊNCIA ATENDIDA","ABAIXO DE 0,50")))) -> SEM ARTIGO VÁLIDO | K22: =IF($A22="","",COUNTIFS('Destaques e PTTs'!$A$2:$A$501,$A22,'Destaques e PTTs'!$C$2:$C$501,"Destaque*",'Destaques e PTTs'!$W$2:$W$501,"OK")) -> 2 | L22: =IF($A22="","",COUNTIFS('Destaques e PTTs'!$A$2:$A$501,$A22,'Destaques e PTTs'!$C$2:$C$501,"PTT adicional*",'Destaques e PTTs'!$W$2:$W$501,"OK")) -> 0 | M22: =IF($A22="","",IF('Orientações'!$B$4="Profissional",IF(AND(K22=2,L22=3),"OK",IF(OR(K22>2,L22>3),"EXCEDE","PENDENTE")),IF(K22=2,"OK",IF(K22>2,"EXCEDE","PENDENTE")))) -> PENDENTE | N22: =IF($A22="","",IF(OR(LOWER($D22)<>"sim",$E22<14,$F22>2,$M22<>"OK",AND(LOWER($C22)<>"sim",G22=0)),"REVISAR","OK")) -> REVISAR
A23: Luana Mendes dos Santos | D23: sim | G23: =IF($A23="","",COUNTIFS('Lançamentos - Artigos'!$A$2:$A$506,$A23,'Lançamentos - Artigos'!$L$2:$L$506,">0")) -> 0 | H23: =IF($A23="","",SUMIFS('Lançamentos - Artigos'!$L$2:$L$506,'Lançamentos - Artigos'!$A$2:$A$506,$A23)) -> 0 | I23: =IF(OR($A23="",G23=0),"",H23/G23) | J23: =IF($A23="","",IF(LOWER($C23)="sim","EXCLUÍDA DO CÁLCULO GERAL",IF(G23=0,"SEM ARTIGO VÁLIDO",IF(I23>=0.5,"REFERÊNCIA ATENDIDA","ABAIXO DE 0,50")))) -> SEM ARTIGO VÁLIDO | K23: =IF($A23="","",COUNTIFS('Destaques e PTTs'!$A$2:$A$501,$A23,'Destaques e PTTs'!$C$2:$C$501,"Destaque*",'Destaques e PTTs'!$W$2:$W$501,"OK")) -> 0 | L23: =IF($A23="","",COUNTIFS('Destaques e PTTs'!$A$2:$A$501,$A23,'Destaques e PTTs'!$C$2:$C$501,"PTT adicional*",'Destaques e PTTs'!$W$2:$W$501,"OK")) -> 0 | M23: =IF($A23="","",IF('Orientações'!$B$4="Profissional",IF(AND(K23=2,L23=3),"OK",IF(OR(K23>2,L23>3),"EXCEDE","PENDENTE")),IF(K23=2,"OK",IF(K23>2,"EXCEDE","PENDENTE")))) -> PENDENTE | N23: =IF($A23="","",IF(OR(LOWER($D23)<>"sim",$E23<14,$F23>2,$M23<>"OK",AND(LOWER($C23)<>"sim",G23=0)),"REVISAR","OK")) -> REVISAR
A24: Volnei Luiz Meneghetti | B24: Inovação, Biotecnologia e Sustentabilidade Produtiva | C24: não | D24: sim | E24: 14 | F24: 1 | G24: =IF($A24="","",COUNTIFS('Lançamentos - Artigos'!$A$2:$A$506,$A24,'Lançamentos - Artigos'!$L$2:$L$506,">0")) -> 0 | H24: =IF($A24="","",SUMIFS('Lançamentos - Artigos'!$L$2:$L$506,'Lançamentos - Artigos'!$A$2:$A$506,$A24)) -> 0 | I24: =IF(OR($A24="",G24=0),"",H24/G24) | J24: =IF($A24="","",IF(LOWER($C24)="sim","EXCLUÍDA DO CÁLCULO GERAL",IF(G24=0,"SEM ARTIGO VÁLIDO",IF(I24>=0.5,"REFERÊNCIA ATENDIDA","ABAIXO DE 0,50")))) -> SEM ARTIGO VÁLIDO | K24: =IF($A24="","",COUNTIFS('Destaques e PTTs'!$A$2:$A$501,$A24,'Destaques e PTTs'!$C$2:$C$501,"Destaque*",'Destaques e PTTs'!$W$2:$W$501,"OK")) -> 1 | L24: =IF($A24="","",COUNTIFS('Destaques e PTTs'!$A$2:$A$501,$A24,'Destaques e PTTs'!$C$2:$C$501,"PTT adicional*",'Destaques e PTTs'!$W$2:$W$501,"OK")) -> 0 | M24: =IF($A24="","",IF('Orientações'!$B$4="Profissional",IF(AND(K24=2,L24=3),"OK",IF(OR(K24>2,L24>3),"EXCEDE","PENDENTE")),IF(K24=2,"OK",IF(K24>2,"EXCEDE","PENDENTE")))) -> PENDENTE | N24: =IF($A24="","",IF(OR(LOWER($D24)<>"sim",$E24<14,$F24>2,$M24<>"OK",AND(LOWER($C24)<>"sim",G24=0)),"REVISAR","OK")) -> REVISAR
D25: sim | G25: =IF($A25="","",COUNTIFS('Lançamentos - Artigos'!$A$2:$A$506,$A25,'Lançamentos - Artigos'!$L$2:$L$506,">0")) | H25: =IF($A25="","",SUMIFS('Lançamentos - Artigos'!$L$2:$L$506,'Lançamentos - Artigos'!$A$2:$A$506,$A25)) | I25: =IF(OR($A25="",G25=0),"",H25/G25) | J25: =IF($A25="","",IF(LOWER($C25)="sim","EXCLUÍDA DO CÁLCULO GERAL",IF(G25=0,"SEM ARTIGO VÁLIDO",IF(I25>=0.5,"REFERÊNCIA ATENDIDA","ABAIXO DE 0,50")))) | K25: =IF($A25="","",COUNTIFS('Destaques e PTTs'!$A$2:$A$501,$A25,'Destaques e PTTs'!$C$2:$C$501,"Destaque*",'Destaques e PTTs'!$W$2:$W$501,"OK")) | L25: =IF($A25="","",COUNTIFS('Destaques e PTTs'!$A$2:$A$501,$A25,'Destaques e PTTs'!$C$2:$C$501,"PTT adicional*",'Destaques e PTTs'!$W$2:$W$501,"OK")) | M25: =IF($A25="","",IF('Orientações'!$B$4="Profissional",IF(AND(K25=2,L25=3),"OK",IF(OR(K25>2,L25>3),"EXCEDE","PENDENTE")),IF(K25=2,"OK",IF(K25>2,"EXCEDE","PENDENTE")))) | N25: =IF($A25="","",IF(OR(LOWER($D25)<>"sim",$E25<14,$F25>2,$M25<>"OK",AND(LOWER($C25)<>"sim",G25=0)),"REVISAR","OK"))
D26: sim | G26: =IF($A26="","",COUNTIFS('Lançamentos - Artigos'!$A$2:$A$506,$A26,'Lançamentos - Artigos'!$L$2:$L$506,">0")) | H26: =IF($A26="","",SUMIFS('Lançamentos - Artigos'!$L$2:$L$506,'Lançamentos - Artigos'!$A$2:$A$506,$A26)) | I26: =IF(OR($A26="",G26=0),"",H26/G26) | J26: =IF($A26="","",IF(LOWER($C26)="sim","EXCLUÍDA DO CÁLCULO GERAL",IF(G26=0,"SEM ARTIGO VÁLIDO",IF(I26>=0.5,"REFERÊNCIA ATENDIDA","ABAIXO DE 0,50")))) | K26: =IF($A26="","",COUNTIFS('Destaques e PTTs'!$A$2:$A$501,$A26,'Destaques e PTTs'!$C$2:$C$501,"Destaque*",'Destaques e PTTs'!$W$2:$W$501,"OK")) | L26: =IF($A26="","",COUNTIFS('Destaques e PTTs'!$A$2:$A$501,$A26,'Destaques e PTTs'!$C$2:$C$501,"PTT adicional*",'Destaques e PTTs'!$W$2:$W$501,"OK")) | M26: =IF($A26="","",IF('Orientações'!$B$4="Profissional",IF(AND(K26=2,L26=3),"OK",IF(OR(K26>2,L26>3),"EXCEDE","PENDENTE")),IF(K26=2,"OK",IF(K26>2,"EXCEDE","PENDENTE")))) | N26: =IF($A26="","",IF(OR(LOWER($D26)<>"sim",$E26<14,$F26>2,$M26<>"OK",AND(LOWER($C26)<>"sim",G26=0)),"REVISAR","OK"))
D27: sim | G27: =IF($A27="","",COUNTIFS('Lançamentos - Artigos'!$A$2:$A$506,$A27,'Lançamentos - Artigos'!$L$2:$L$506,">0")) | H27: =IF($A27="","",SUMIFS('Lançamentos - Artigos'!$L$2:$L$506,'Lançamentos - Artigos'!$A$2:$A$506,$A27)) | I27: =IF(OR($A27="",G27=0),"",H27/G27) | J27: =IF($A27="","",IF(LOWER($C27)="sim","EXCLUÍDA DO CÁLCULO GERAL",IF(G27=0,"SEM ARTIGO VÁLIDO",IF(I27>=0.5,"REFERÊNCIA ATENDIDA","ABAIXO DE 0,50")))) | K27: =IF($A27="","",COUNTIFS('Destaques e PTTs'!$A$2:$A$501,$A27,'Destaques e PTTs'!$C$2:$C$501,"Destaque*",'Destaques e PTTs'!$W$2:$W$501,"OK")) | L27: =IF($A27="","",COUNTIFS('Destaques e PTTs'!$A$2:$A$501,$A27,'Destaques e PTTs'!$C$2:$C$501,"PTT adicional*",'Destaques e PTTs'!$W$2:$W$501,"OK")) | M27: =IF($A27="","",IF('Orientações'!$B$4="Profissional",IF(AND(K27=2,L27=3),"OK",IF(OR(K27>2,L27>3),"EXCEDE","PENDENTE")),IF(K27=2,"OK",IF(K27>2,"EXCEDE","PENDENTE")))) | N27: =IF($A27="","",IF(OR(LOWER($D27)<>"sim",$E27<14,$F27>2,$M27<>"OK",AND(LOWER($C27)<>"sim",G27=0)),"REVISAR","OK"))
D28: sim | G28: =IF($A28="","",COUNTIFS('Lançamentos - Artigos'!$A$2:$A$506,$A28,'Lançamentos - Artigos'!$L$2:$L$506,">0")) | H28: =IF($A28="","",SUMIFS('Lançamentos - Artigos'!$L$2:$L$506,'Lançamentos - Artigos'!$A$2:$A$506,$A28)) | I28: =IF(OR($A28="",G28=0),"",H28/G28) | J28: =IF($A28="","",IF(LOWER($C28)="sim","EXCLUÍDA DO CÁLCULO GERAL",IF(G28=0,"SEM ARTIGO VÁLIDO",IF(I28>=0.5,"REFERÊNCIA ATENDIDA","ABAIXO DE 0,50")))) | K28: =IF($A28="","",COUNTIFS('Destaques e PTTs'!$A$2:$A$501,$A28,'Destaques e PTTs'!$C$2:$C$501,"Destaque*",'Destaques e PTTs'!$W$2:$W$501,"OK")) | L28: =IF($A28="","",COUNTIFS('Destaques e PTTs'!$A$2:$A$501,$A28,'Destaques e PTTs'!$C$2:$C$501,"PTT adicional*",'Destaques e PTTs'!$W$2:$W$501,"OK")) | M28: =IF($A28="","",IF('Orientações'!$B$4="Profissional",IF(AND(K28=2,L28=3),"OK",IF(OR(K28>2,L28>3),"EXCEDE","PENDENTE")),IF(K28=2,"OK",IF(K28>2,"EXCEDE","PENDENTE")))) | N28: =IF($A28="","",IF(OR(LOWER($D28)<>"sim",$E28<14,$F28>2,$M28<>"OK",AND(LOWER($C28)<>"sim",G28=0)),"REVISAR","OK"))
D29: sim | G29: =IF($A29="","",COUNTIFS('Lançamentos - Artigos'!$A$2:$A$506,$A29,'Lançamentos - Artigos'!$L$2:$L$506,">0")) | H29: =IF($A29="","",SUMIFS('Lançamentos - Artigos'!$L$2:$L$506,'Lançamentos - Artigos'!$A$2:$A$506,$A29)) | I29: =IF(OR($A29="",G29=0),"",H29/G29) | J29: =IF($A29="","",IF(LOWER($C29)="sim","EXCLUÍDA DO CÁLCULO GERAL",IF(G29=0,"SEM ARTIGO VÁLIDO",IF(I29>=0.5,"REFERÊNCIA ATENDIDA","ABAIXO DE 0,50")))) | K29: =IF($A29="","",COUNTIFS('Destaques e PTTs'!$A$2:$A$501,$A29,'Destaques e PTTs'!$C$2:$C$501,"Destaque*",'Destaques e PTTs'!$W$2:$W$501,"OK")) | L29: =IF($A29="","",COUNTIFS('Destaques e PTTs'!$A$2:$A$501,$A29,'Destaques e PTTs'!$C$2:$C$501,"PTT adicional*",'Destaques e PTTs'!$W$2:$W$501,"OK")) | M29: =IF($A29="","",IF('Orientações'!$B$4="Profissional",IF(AND(K29=2,L29=3),"OK",IF(OR(K29>2,L29>3),"EXCEDE","PENDENTE")),IF(K29=2,"OK",IF(K29>2,"EXCEDE","PENDENTE")))) | N29: =IF($A29="","",IF(OR(LOWER($D29)<>"sim",$E29<14,$F29>2,$M29<>"OK",AND(LOWER($C29)<>"sim",G29=0)),"REVISAR","OK"))
D30: sim | G30: =IF($A30="","",COUNTIFS('Lançamentos - Artigos'!$A$2:$A$506,$A30,'Lançamentos - Artigos'!$L$2:$L$506,">0")) | H30: =IF($A30="","",SUMIFS('Lançamentos - Artigos'!$L$2:$L$506,'Lançamentos - Artigos'!$A$2:$A$506,$A30)) | I30: =IF(OR($A30="",G30=0),"",H30/G30) | J30: =IF($A30="","",IF(LOWER($C30)="sim","EXCLUÍDA DO CÁLCULO GERAL",IF(G30=0,"SEM ARTIGO VÁLIDO",IF(I30>=0.5,"REFERÊNCIA ATENDIDA","ABAIXO DE 0,50")))) | K30: =IF($A30="","",COUNTIFS('Destaques e PTTs'!$A$2:$A$501,$A30,'Destaques e PTTs'!$C$2:$C$501,"Destaque*",'Destaques e PTTs'!$W$2:$W$501,"OK")) | L30: =IF($A30="","",COUNTIFS('Destaques e PTTs'!$A$2:$A$501,$A30,'Destaques e PTTs'!$C$2:$C$501,"PTT adicional*",'Destaques e PTTs'!$W$2:$W$501,"OK")) | M30: =IF($A30="","",IF('Orientações'!$B$4="Profissional",IF(AND(K30=2,L30=3),"OK",IF(OR(K30>2,L30>3),"EXCEDE","PENDENTE")),IF(K30=2,"OK",IF(K30>2,"EXCEDE","PENDENTE")))) | N30: =IF($A30="","",IF(OR(LOWER($D30)<>"sim",$E30<14,$F30>2,$M30<>"OK",AND(LOWER($C30)<>"sim",G30=0)),"REVISAR","OK"))
D31: sim | G31: =IF($A31="","",COUNTIFS('Lançamentos - Artigos'!$A$2:$A$506,$A31,'Lançamentos - Artigos'!$L$2:$L$506,">0")) | H31: =IF($A31="","",SUMIFS('Lançamentos - Artigos'!$L$2:$L$506,'Lançamentos - Artigos'!$A$2:$A$506,$A31)) | I31: =IF(OR($A31="",G31=0),"",H31/G31) | J31: =IF($A31="","",IF(LOWER($C31)="sim","EXCLUÍDA DO CÁLCULO GERAL",IF(G31=0,"SEM ARTIGO VÁLIDO",IF(I31>=0.5,"REFERÊNCIA ATENDIDA","ABAIXO DE 0,50")))) | K31: =IF($A31="","",COUNTIFS('Destaques e PTTs'!$A$2:$A$501,$A31,'Destaques e PTTs'!$C$2:$C$501,"Destaque*",'Destaques e PTTs'!$W$2:$W$501,"OK")) | L31: =IF($A31="","",COUNTIFS('Destaques e PTTs'!$A$2:$A$501,$A31,'Destaques e PTTs'!$C$2:$C$501,"PTT adicional*",'Destaques e PTTs'!$W$2:$W$501,"OK")) | M31: =IF($A31="","",IF('Orientações'!$B$4="Profissional",IF(AND(K31=2,L31=3),"OK",IF(OR(K31>2,L31>3),"EXCEDE","PENDENTE")),IF(K31=2,"OK",IF(K31>2,"EXCEDE","PENDENTE")))) | N31: =IF($A31="","",IF(OR(LOWER($D31)<>"sim",$E31<14,$F31>2,$M31<>"OK",AND(LOWER($C31)<>"sim",G31=0)),"REVISAR","OK"))
D32: sim | G32: =IF($A32="","",COUNTIFS('Lançamentos - Artigos'!$A$2:$A$506,$A32,'Lançamentos - Artigos'!$L$2:$L$506,">0")) | H32: =IF($A32="","",SUMIFS('Lançamentos - Artigos'!$L$2:$L$506,'Lançamentos - Artigos'!$A$2:$A$506,$A32)) | I32: =IF(OR($A32="",G32=0),"",H32/G32) | J32: =IF($A32="","",IF(LOWER($C32)="sim","EXCLUÍDA DO CÁLCULO GERAL",IF(G32=0,"SEM ARTIGO VÁLIDO",IF(I32>=0.5,"REFERÊNCIA ATENDIDA","ABAIXO DE 0,50")))) | K32: =IF($A32="","",COUNTIFS('Destaques e PTTs'!$A$2:$A$501,$A32,'Destaques e PTTs'!$C$2:$C$501,"Destaque*",'Destaques e PTTs'!$W$2:$W$501,"OK")) | L32: =IF($A32="","",COUNTIFS('Destaques e PTTs'!$A$2:$A$501,$A32,'Destaques e PTTs'!$C$2:$C$501,"PTT adicional*",'Destaques e PTTs'!$W$2:$W$501,"OK")) | M32: =IF($A32="","",IF('Orientações'!$B$4="Profissional",IF(AND(K32=2,L32=3),"OK",IF(OR(K32>2,L32>3),"EXCEDE","PENDENTE")),IF(K32=2,"OK",IF(K32>2,"EXCEDE","PENDENTE")))) | N32: =IF($A32="","",IF(OR(LOWER($D32)<>"sim",$E32<14,$F32>2,$M32<>"OK",AND(LOWER($C32)<>"sim",G32=0)),"REVISAR","OK"))
D33: sim | G33: =IF($A33="","",COUNTIFS('Lançamentos - Artigos'!$A$2:$A$506,$A33,'Lançamentos - Artigos'!$L$2:$L$506,">0")) | H33: =IF($A33="","",SUMIFS('Lançamentos - Artigos'!$L$2:$L$506,'Lançamentos - Artigos'!$A$2:$A$506,$A33)) | I33: =IF(OR($A33="",G33=0),"",H33/G33) | J33: =IF($A33="","",IF(LOWER($C33)="sim","EXCLUÍDA DO CÁLCULO GERAL",IF(G33=0,"SEM ARTIGO VÁLIDO",IF(I33>=0.5,"REFERÊNCIA ATENDIDA","ABAIXO DE 0,50")))) | K33: =IF($A33="","",COUNTIFS('Destaques e PTTs'!$A$2:$A$501,$A33,'Destaques e PTTs'!$C$2:$C$501,"Destaque*",'Destaques e PTTs'!$W$2:$W$501,"OK")) | L33: =IF($A33="","",COUNTIFS('Destaques e PTTs'!$A$2:$A$501,$A33,'Destaques e PTTs'!$C$2:$C$501,"PTT adicional*",'Destaques e PTTs'!$W$2:$W$501,"OK")) | M33: =IF($A33="","",IF('Orientações'!$B$4="Profissional",IF(AND(K33=2,L33=3),"OK",IF(OR(K33>2,L33>3),"EXCEDE","PENDENTE")),IF(K33=2,"OK",IF(K33>2,"EXCEDE","PENDENTE")))) | N33: =IF($A33="","",IF(OR(LOWER($D33)<>"sim",$E33<14,$F33>2,$M33<>"OK",AND(LOWER($C33)<>"sim",G33=0)),"REVISAR","OK"))
D34: sim | G34: =IF($A34="","",COUNTIFS('Lançamentos - Artigos'!$A$2:$A$506,$A34,'Lançamentos - Artigos'!$L$2:$L$506,">0")) | H34: =IF($A34="","",SUMIFS('Lançamentos - Artigos'!$L$2:$L$506,'Lançamentos - Artigos'!$A$2:$A$506,$A34)) | I34: =IF(OR($A34="",G34=0),"",H34/G34) | J34: =IF($A34="","",IF(LOWER($C34)="sim","EXCLUÍDA DO CÁLCULO GERAL",IF(G34=0,"SEM ARTIGO VÁLIDO",IF(I34>=0.5,"REFERÊNCIA ATENDIDA","ABAIXO DE 0,50")))) | K34: =IF($A34="","",COUNTIFS('Destaques e PTTs'!$A$2:$A$501,$A34,'Destaques e PTTs'!$C$2:$C$501,"Destaque*",'Destaques e PTTs'!$W$2:$W$501,"OK")) | L34: =IF($A34="","",COUNTIFS('Destaques e PTTs'!$A$2:$A$501,$A34,'Destaques e PTTs'!$C$2:$C$501,"PTT adicional*",'Destaques e PTTs'!$W$2:$W$501,"OK")) | M34: =IF($A34="","",IF('Orientações'!$B$4="Profissional",IF(AND(K34=2,L34=3),"OK",IF(OR(K34>2,L34>3),"EXCEDE","PENDENTE")),IF(K34=2,"OK",IF(K34>2,"EXCEDE","PENDENTE")))) | N34: =IF($A34="","",IF(OR(LOWER($D34)<>"sim",$E34<14,$F34>2,$M34<>"OK",AND(LOWER($C34)<>"sim",G34=0)),"REVISAR","OK"))
D35: sim | G35: =IF($A35="","",COUNTIFS('Lançamentos - Artigos'!$A$2:$A$506,$A35,'Lançamentos - Artigos'!$L$2:$L$506,">0")) | H35: =IF($A35="","",SUMIFS('Lançamentos - Artigos'!$L$2:$L$506,'Lançamentos - Artigos'!$A$2:$A$506,$A35)) | I35: =IF(OR($A35="",G35=0),"",H35/G35) | J35: =IF($A35="","",IF(LOWER($C35)="sim","EXCLUÍDA DO CÁLCULO GERAL",IF(G35=0,"SEM ARTIGO VÁLIDO",IF(I35>=0.5,"REFERÊNCIA ATENDIDA","ABAIXO DE 0,50")))) | K35: =IF($A35="","",COUNTIFS('Destaques e PTTs'!$A$2:$A$501,$A35,'Destaques e PTTs'!$C$2:$C$501,"Destaque*",'Destaques e PTTs'!$W$2:$W$501,"OK")) | L35: =IF($A35="","",COUNTIFS('Destaques e PTTs'!$A$2:$A$501,$A35,'Destaques e PTTs'!$C$2:$C$501,"PTT adicional*",'Destaques e PTTs'!$W$2:$W$501,"OK")) | M35: =IF($A35="","",IF('Orientações'!$B$4="Profissional",IF(AND(K35=2,L35=3),"OK",IF(OR(K35>2,L35>3),"EXCEDE","PENDENTE")),IF(K35=2,"OK",IF(K35>2,"EXCEDE","PENDENTE")))) | N35: =IF($A35="","",IF(OR(LOWER($D35)<>"sim",$E35<14,$F35>2,$M35<>"OK",AND(LOWER($C35)<>"sim",G35=0)),"REVISAR","OK"))
D36: sim | G36: =IF($A36="","",COUNTIFS('Lançamentos - Artigos'!$A$2:$A$506,$A36,'Lançamentos - Artigos'!$L$2:$L$506,">0")) | H36: =IF($A36="","",SUMIFS('Lançamentos - Artigos'!$L$2:$L$506,'Lançamentos - Artigos'!$A$2:$A$506,$A36)) | I36: =IF(OR($A36="",G36=0),"",H36/G36) | J36: =IF($A36="","",IF(LOWER($C36)="sim","EXCLUÍDA DO CÁLCULO GERAL",IF(G36=0,"SEM ARTIGO VÁLIDO",IF(I36>=0.5,"REFERÊNCIA ATENDIDA","ABAIXO DE 0,50")))) | K36: =IF($A36="","",COUNTIFS('Destaques e PTTs'!$A$2:$A$501,$A36,'Destaques e PTTs'!$C$2:$C$501,"Destaque*",'Destaques e PTTs'!$W$2:$W$501,"OK")) | L36: =IF($A36="","",COUNTIFS('Destaques e PTTs'!$A$2:$A$501,$A36,'Destaques e PTTs'!$C$2:$C$501,"PTT adicional*",'Destaques e PTTs'!$W$2:$W$501,"OK")) | M36: =IF($A36="","",IF('Orientações'!$B$4="Profissional",IF(AND(K36=2,L36=3),"OK",IF(OR(K36>2,L36>3),"EXCEDE","PENDENTE")),IF(K36=2,"OK",IF(K36>2,"EXCEDE","PENDENTE")))) | N36: =IF($A36="","",IF(OR(LOWER($D36)<>"sim",$E36<14,$F36>2,$M36<>"OK",AND(LOWER($C36)<>"sim",G36=0)),"REVISAR","OK"))
... D57: sim | G57: =IF($A57="","",COUNTIFS('Lançamentos - Artigos'!$A$2:$A$506,$A57,'Lançamentos - Artigos'!$L$2:$L$506,">0")) | H57: =IF($A57="","",SUMIFS('Lançamentos - Artigos'!$L$2:$L$506,'Lançamentos - Artigos'!$A$2:$A$506,$A57)) | I57: =IF(OR($A57="",G57=0),"",H57/G57) | J57: =IF($A57="","",IF(LOWER($C57)="sim","EXCLUÍDA DO CÁLCULO GERAL",IF(G57=0,"SEM ARTIGO VÁLIDO",IF(I57>=0.5,"REFERÊNCIA ATENDIDA","ABAIXO DE 0,50")))) | K57: =IF($A57="","",COUNTIFS('Destaques e PTTs'!$A$2:$A$501,$A57,'Destaques e PTTs'!$C$2:$C$501,"Destaque*",'Destaques e PTTs'!$W$2:$W$501,"OK")) | L57: =IF($A57="","",COUNTIFS('Destaques e PTTs'!$A$2:$A$501,$A57,'Destaques e PTTs'!$C$2:$C$501,"PTT adicional*",'Destaques e PTTs'!$W$2:$W$501,"OK")) | M57: =IF($A57="","",IF('Orientações'!$B$4="Profissional",IF(AND(K57=2,L57=3),"OK",IF(OR(K57>2,L57>3),"EXCEDE","PENDENTE")),IF(K57=2,"OK",IF(K57>2,"EXCEDE","PENDENTE")))) | N57: =IF($A57="","",IF(OR(LOWER($D57)<>"sim",$E57<14,$F57>2,$M57<>"OK",AND(LOWER($C57)<>"sim",G57=0)),"REVISAR","OK"))

Sheet Lançamentos - Artigos
A1: Docente | B1: Linha de pesquisa/atuação | C1: Ano | D1: Título do artigo | E1: DOI | F1: País do periódico | G1: Base usada | H1: Percentil WoS/Scopus | I1: Dimensions: maior % de artigos citados | J1: Dimensions: média de citações | K1: Índice CAPES | L1: Índice válido | M1: FWCI/ICPC | N1: No Lattes? | O1: Aderente à proposta? | P1: Observações
A2: Anderson Saldanha Bueno | B2: =IF($A2="","",IFERROR(VLOOKUP($A2,'Resumo por docente'!$A$8:$B$57,2,FALSE),"")) -> Biodiversidade, Saúde Ambiental e Conservação | C2: 2026 | D2: Patterns of understorey bird diversity across Amazonian forests: survey effort and range maps predict local species richness | E2: https://doi.org/10.1002/ecog.07625 | K2: =IF($A2="","",IF(OR($G2="WoS",$G2="Scopus"),IF($H2="","",IF($H2>=87.5,1,IF($H2>=75,0.875,IF($H2>=62.5,0.75,IF($H2>=50,0.625,IF($H2>=37.5,0.5,IF($H2>=25,0.375,IF($H2>=12.5,0.25,IF($H2>=0.01,0.125,0))))))))),IF($G2="Dimensions",IF(OR($I2="",$J2=""),"",MIN(IF($I2>=87.5,1,IF($I2>=75,0.875,IF($I2>=62.5,0.75,IF($I2>=50,0.625,IF($I2>=37.5,0.5,IF($I2>=25,0.375,IF($I2>=12.5,0.25,IF($I2>=0.01,0.125,0)))))))),IF($J2>=2,1,IF($J2>=1.5,0.875,IF($J2>=1,0.75,IF($J2>=0.75,0.625,IF($J2>=0.5,0.5,IF($J2>=0.25,0.375,IF($J2>=0.125,0.25,IF($J2>=0.01,0.125,0)))))))))),""))) | L2: =IF($A2="","",IF(AND($C2>=2021,$C2<=2026,$E2<>"",$K2>0,LOWER($N2)="sim",LOWER($O2)="sim",OR(AND($F2="Exterior",OR($G2="WoS",$G2="Scopus")),AND($F2="Brasil",OR(AND(OR($G2="WoS",$G2="Scopus"),$H2>=50),$G2="Dimensions")))),$K2,"")) | N2: sim
A3: Anderson Saldanha Bueno | B3: =IF($A3="","",IFERROR(VLOOKUP($A3,'Resumo por docente'!$A$8:$B$57,2,FALSE),"")) -> Biodiversidade, Saúde Ambiental e Conservação | C3: 2026 | D3: High-quality surrounding landscapes mitigate avian extirpations from forest remnants | E3: https://doi.org/10.1073/pnas.2521783123 | K3: =IF($A3="","",IF(OR($G3="WoS",$G3="Scopus"),IF($H3="","",IF($H3>=87.5,1,IF($H3>=75,0.875,IF($H3>=62.5,0.75,IF($H3>=50,0.625,IF($H3>=37.5,0.5,IF($H3>=25,0.375,IF($H3>=12.5,0.25,IF($H3>=0.01,0.125,0))))))))),IF($G3="Dimensions",IF(OR($I3="",$J3=""),"",MIN(IF($I3>=87.5,1,IF($I3>=75,0.875,IF($I3>=62.5,0.75,IF($I3>=50,0.625,IF($I3>=37.5,0.5,IF($I3>=25,0.375,IF($I3>=12.5,0.25,IF($I3>=0.01,0.125,0)))))))),IF($J3>=2,1,IF($J3>=1.5,0.875,IF($J3>=1,0.75,IF($J3>=0.75,0.625,IF($J3>=0.5,0.5,IF($J3>=0.25,0.375,IF($J3>=0.125,0.25,IF($J3>=0.01,0.125,0)))))))))),""))) | L3: =IF($A3="","",IF(AND($C3>=2021,$C3<=2026,$E3<>"",$K3>0,LOWER($N3)="sim",LOWER($O3)="sim",OR(AND($F3="Exterior",OR($G3="WoS",$G3="Scopus")),AND($F3="Brasil",OR(AND(OR($G3="WoS",$G3="Scopus"),$H3>=50),$G3="Dimensions")))),$K3,"")) | N3: sim
A4: Anderson Saldanha Bueno | B4: =IF($A4="","",IFERROR(VLOOKUP($A4,'Resumo por docente'!$A$8:$B$57,2,FALSE),"")) -> Biodiversidade, Saúde Ambiental e Conservação | C4: 2026 | D4: Habitat insularization alters taxonomic and functional beta diversity of understorey birds in Amazonian forest islands | E4: https://doi.org/10.1098/rsos.260165 | K4: =IF($A4="","",IF(OR($G4="WoS",$G4="Scopus"),IF($H4="","",IF($H4>=87.5,1,IF($H4>=75,0.875,IF($H4>=62.5,0.75,IF($H4>=50,0.625,IF($H4>=37.5,0.5,IF($H4>=25,0.375,IF($H4>=12.5,0.25,IF($H4>=0.01,0.125,0))))))))),IF($G4="Dimensions",IF(OR($I4="",$J4=""),"",MIN(IF($I4>=87.5,1,IF($I4>=75,0.875,IF($I4>=62.5,0.75,IF($I4>=50,0.625,IF($I4>=37.5,0.5,IF($I4>=25,0.375,IF($I4>=12.5,0.25,IF($I4>=0.01,0.125,0)))))))),IF($J4>=2,1,IF($J4>=1.5,0.875,IF($J4>=1,0.75,IF($J4>=0.75,0.625,IF($J4>=0.5,0.5,IF($J4>=0.25,0.375,IF($J4>=0.125,0.25,IF($J4>=0.01,0.125,0)))))))))),""))) | L4: =IF($A4="","",IF(AND($C4>=2021,$C4<=2026,$E4<>"",$K4>0,LOWER($N4)="sim",LOWER($O4)="sim",OR(AND($F4="Exterior",OR($G4="WoS",$G4="Scopus")),AND($F4="Brasil",OR(AND(OR($G4="WoS",$G4="Scopus"),$H4>=50),$G4="Dimensions")))),$K4,"")) | N4: sim
A5: Anderson Saldanha Bueno | B5: =IF($A5="","",IFERROR(VLOOKUP($A5,'Resumo por docente'!$A$8:$B$57,2,FALSE),"")) -> Biodiversidade, Saúde Ambiental e Conservação | C5: 2025 | D5: Evaluation of multiple water immersions of pathogen vector mosquito (Diptera: Culicidae) eggs | E5: https://doi.org/10.3389/fitd.2025.1590603 | K5: =IF($A5="","",IF(OR($G5="WoS",$G5="Scopus"),IF($H5="","",IF($H5>=87.5,1,IF($H5>=75,0.875,IF($H5>=62.5,0.75,IF($H5>=50,0.625,IF($H5>=37.5,0.5,IF($H5>=25,0.375,IF($H5>=12.5,0.25,IF($H5>=0.01,0.125,0))))))))),IF($G5="Dimensions",IF(OR($I5="",$J5=""),"",MIN(IF($I5>=87.5,1,IF($I5>=75,0.875,IF($I5>=62.5,0.75,IF($I5>=50,0.625,IF($I5>=37.5,0.5,IF($I5>=25,0.375,IF($I5>=12.5,0.25,IF($I5>=0.01,0.125,0)))))))),IF($J5>=2,1,IF($J5>=1.5,0.875,IF($J5>=1,0.75,IF($J5>=0.75,0.625,IF($J5>=0.5,0.5,IF($J5>=0.25,0.375,IF($J5>=0.125,0.25,IF($J5>=0.01,0.125,0)))))))))),""))) | L5: =IF($A5="","",IF(AND($C5>=2021,$C5<=2026,$E5<>"",$K5>0,LOWER($N5)="sim",LOWER($O5)="sim",OR(AND($F5="Exterior",OR($G5="WoS",$G5="Scopus")),AND($F5="Brasil",OR(AND(OR($G5="WoS",$G5="Scopus"),$H5>=50),$G5="Dimensions")))),$K5,"")) | N5: sim
A6: Anderson Saldanha Bueno | B6: =IF($A6="","",IFERROR(VLOOKUP($A6,'Resumo por docente'!$A$8:$B$57,2,FALSE),"")) -> Biodiversidade, Saúde Ambiental e Conservação | C6: 2025 | D6: Tree plantations inserted in a benign environmental context can contribute to the maintenance of forest avifauna | E6: https://doi.org/10.1016/j.foreco.2025.122985 | K6: =IF($A6="","",IF(OR($G6="WoS",$G6="Scopus"),IF($H6="","",IF($H6>=87.5,1,IF($H6>=75,0.875,IF($H6>=62.5,0.75,IF($H6>=50,0.625,IF($H6>=37.5,0.5,IF($H6>=25,0.375,IF($H6>=12.5,0.25,IF($H6>=0.01,0.125,0))))))))),IF($G6="Dimensions",IF(OR($I6="",$J6=""),"",MIN(IF($I6>=87.5,1,IF($I6>=75,0.875,IF($I6>=62.5,0.75,IF($I6>=50,0.625,IF($I6>=37.5,0.5,IF($I6>=25,0.375,IF($I6>=12.5,0.25,IF($I6>=0.01,0.125,0)))))))),IF($J6>=2,1,IF($J6>=1.5,0.875,IF($J6>=1,0.75,IF($J6>=0.75,0.625,IF($J6>=0.5,0.5,IF($J6>=0.25,0.375,IF($J6>=0.125,0.25,IF($J6>=0.01,0.125,0)))))))))),""))) | L6: =IF($A6="","",IF(AND($C6>=2021,$C6<=2026,$E6<>"",$K6>0,LOWER($N6)="sim",LOWER($O6)="sim",OR(AND($F6="Exterior",OR($G6="WoS",$G6="Scopus")),AND($F6="Brasil",OR(AND(OR($G6="WoS",$G6="Scopus"),$H6>=50),$G6="Dimensions")))),$K6,"")) | N6: sim
A7: Anderson Saldanha Bueno | B7: =IF($A7="","",IFERROR(VLOOKUP($A7,'Resumo por docente'!$A$8:$B$57,2,FALSE),"")) -> Biodiversidade, Saúde Ambiental e Conservação | C7: 2025 | D7: Protocolo de amostragem da biodiversidade via monitoramento acústico passivo | K7: =IF($A7="","",IF(OR($G7="WoS",$G7="Scopus"),IF($H7="","",IF($H7>=87.5,1,IF($H7>=75,0.875,IF($H7>=62.5,0.75,IF($H7>=50,0.625,IF($H7>=37.5,0.5,IF($H7>=25,0.375,IF($H7>=12.5,0.25,IF($H7>=0.01,0.125,0))))))))),IF($G7="Dimensions",IF(OR($I7="",$J7=""),"",MIN(IF($I7>=87.5,1,IF($I7>=75,0.875,IF($I7>=62.5,0.75,IF($I7>=50,0.625,IF($I7>=37.5,0.5,IF($I7>=25,0.375,IF($I7>=12.5,0.25,IF($I7>=0.01,0.125,0)))))))),IF($J7>=2,1,IF($J7>=1.5,0.875,IF($J7>=1,0.75,IF($J7>=0.75,0.625,IF($J7>=0.5,0.5,IF($J7>=0.25,0.375,IF($J7>=0.125,0.25,IF($J7>=0.01,0.125,0)))))))))),""))) | L7: =IF($A7="","",IF(AND($C7>=2021,$C7<=2026,$E7<>"",$K7>0,LOWER($N7)="sim",LOWER($O7)="sim",OR(AND($F7="Exterior",OR($G7="WoS",$G7="Scopus")),AND($F7="Brasil",OR(AND(OR($G7="WoS",$G7="Scopus"),$H7>=50),$G7="Dimensions")))),$K7,"")) | N7: sim
A8: Anderson Saldanha Bueno | B8: =IF($A8="","",IFERROR(VLOOKUP($A8,'Resumo por docente'!$A$8:$B$57,2,FALSE),"")) -> Biodiversidade, Saúde Ambiental e Conservação | C8: 2025 | D8: Protocolo de amostragem de aves em parcelas RAPELD | K8: =IF($A8="","",IF(OR($G8="WoS",$G8="Scopus"),IF($H8="","",IF($H8>=87.5,1,IF($H8>=75,0.875,IF($H8>=62.5,0.75,IF($H8>=50,0.625,IF($H8>=37.5,0.5,IF($H8>=25,0.375,IF($H8>=12.5,0.25,IF($H8>=0.01,0.125,0))))))))),IF($G8="Dimensions",IF(OR($I8="",$J8=""),"",MIN(IF($I8>=87.5,1,IF($I8>=75,0.875,IF($I8>=62.5,0.75,IF($I8>=50,0.625,IF($I8>=37.5,0.5,IF($I8>=25,0.375,IF($I8>=12.5,0.25,IF($I8>=0.01,0.125,0)))))))),IF($J8>=2,1,IF($J8>=1.5,0.875,IF($J8>=1,0.75,IF($J8>=0.75,0.625,IF($J8>=0.5,0.5,IF($J8>=0.25,0.375,IF($J8>=0.125,0.25,IF($J8>=0.01,0.125,0)))))))))),""))) | L8: =IF($A8="","",IF(AND($C8>=2021,$C8<=2026,$E8<>"",$K8>0,LOWER($N8)="sim",LOWER($O8)="sim",OR(AND($F8="Exterior",OR($G8="WoS",$G8="Scopus")),AND($F8="Brasil",OR(AND(OR($G8="WoS",$G8="Scopus"),$H8>=50),$G8="Dimensions")))),$K8,"")) | N8: sim
A9: Anderson Saldanha Bueno | B9: =IF($A9="","",IFERROR(VLOOKUP($A9,'Resumo por docente'!$A$8:$B$57,2,FALSE),"")) -> Biodiversidade, Saúde Ambiental e Conservação | C9: 2025 | D9: Forest structure predicts plant and animal species diversity and composition changes in an Amazonian forest | E9: https://doi.org/10.1007/s10531-025-03136-4 | K9: =IF($A9="","",IF(OR($G9="WoS",$G9="Scopus"),IF($H9="","",IF($H9>=87.5,1,IF($H9>=75,0.875,IF($H9>=62.5,0.75,IF($H9>=50,0.625,IF($H9>=37.5,0.5,IF($H9>=25,0.375,IF($H9>=12.5,0.25,IF($H9>=0.01,0.125,0))))))))),IF($G9="Dimensions",IF(OR($I9="",$J9=""),"",MIN(IF($I9>=87.5,1,IF($I9>=75,0.875,IF($I9>=62.5,0.75,IF($I9>=50,0.625,IF($I9>=37.5,0.5,IF($I9>=25,0.375,IF($I9>=12.5,0.25,IF($I9>=0.01,0.125,0)))))))),IF($J9>=2,1,IF($J9>=1.5,0.875,IF($J9>=1,0.75,IF($J9>=0.75,0.625,IF($J9>=0.5,0.5,IF($J9>=0.25,0.375,IF($J9>=0.125,0.25,IF($J9>=0.01,0.125,0)))))))))),""))) | L9: =IF($A9="","",IF(AND($C9>=2021,$C9<=2026,$E9<>"",$K9>0,LOWER($N9)="sim",LOWER($O9)="sim",OR(AND($F9="Exterior",OR($G9="WoS",$G9="Scopus")),AND($F9="Brasil",OR(AND(OR($G9="WoS",$G9="Scopus"),$H9>=50),$G9="Dimensions")))),$K9,"")) | N9: sim
A10: Anderson Saldanha Bueno | B10: =IF($A10="","",IFERROR(VLOOKUP($A10,'Resumo por docente'!$A$8:$B$57,2,FALSE),"")) -> Biodiversidade, Saúde Ambiental e Conservação | C10: 2025 | D10: How much sampling is enough? Four decades of understorey bird mist-netting across Amazonia define the minimum effort to uncover species assemblage structure | E10: https://doi.org/10.1111/ibi.70015 | K10: =IF($A10="","",IF(OR($G10="WoS",$G10="Scopus"),IF($H10="","",IF($H10>=87.5,1,IF($H10>=75,0.875,IF($H10>=62.5,0.75,IF($H10>=50,0.625,IF($H10>=37.5,0.5,IF($H10>=25,0.375,IF($H10>=12.5,0.25,IF($H10>=0.01,0.125,0))))))))),IF($G10="Dimensions",IF(OR($I10="",$J10=""),"",MIN(IF($I10>=87.5,1,IF($I10>=75,0.875,IF($I10>=62.5,0.75,IF($I10>=50,0.625,IF($I10>=37.5,0.5,IF($I10>=25,0.375,IF($I10>=12.5,0.25,IF($I10>=0.01,0.125,0)))))))),IF($J10>=2,1,IF($J10>=1.5,0.875,IF($J10>=1,0.75,IF($J10>=0.75,0.625,IF($J10>=0.5,0.5,IF($J10>=0.25,0.375,IF($J10>=0.125,0.25,IF($J10>=0.01,0.125,0)))))))))),""))) | L10: =IF($A10="","",IF(AND($C10>=2021,$C10<=2026,$E10<>"",$K10>0,LOWER($N10)="sim",LOWER($O10)="sim",OR(AND($F10="Exterior",OR($G10="WoS",$G10="Scopus")),AND($F10="Brasil",OR(AND(OR($G10="WoS",$G10="Scopus"),$H10>=50),$G10="Dimensions")))),$K10,"")) | N10: sim
A11: Anderson Saldanha Bueno | B11: =IF($A11="","",IFERROR(VLOOKUP($A11,'Resumo por docente'!$A$8:$B$57,2,FALSE),"")) -> Biodiversidade, Saúde Ambiental e Conservação | C11: 2024 | D11: Disentangling the veil line for Brazilian biodiversity: An overview from two long-term research programs reveals huge gaps in ecological data reporting | E11: https://doi.org/10.1016/j.scitotenv.2024.174880 | K11: =IF($A11="","",IF(OR($G11="WoS",$G11="Scopus"),IF($H11="","",IF($H11>=87.5,1,IF($H11>=75,0.875,IF($H11>=62.5,0.75,IF($H11>=50,0.625,IF($H11>=37.5,0.5,IF($H11>=25,0.375,IF($H11>=12.5,0.25,IF($H11>=0.01,0.125,0))))))))),IF($G11="Dimensions",IF(OR($I11="",$J11=""),"",MIN(IF($I11>=87.5,1,IF($I11>=75,0.875,IF($I11>=62.5,0.75,IF($I11>=50,0.625,IF($I11>=37.5,0.5,IF($I11>=25,0.375,IF($I11>=12.5,0.25,IF($I11>=0.01,0.125,0)))))))),IF($J11>=2,1,IF($J11>=1.5,0.875,IF($J11>=1,0.75,IF($J11>=0.75,0.625,IF($J11>=0.5,0.5,IF($J11>=0.25,0.375,IF($J11>=0.125,0.25,IF($J11>=0.01,0.125,0)))))))))),""))) | L11: =IF($A11="","",IF(AND($C11>=2021,$C11<=2026,$E11<>"",$K11>0,LOWER($N11)="sim",LOWER($O11)="sim",OR(AND($F11="Exterior",OR($G11="WoS",$G11="Scopus")),AND($F11="Brasil",OR(AND(OR($G11="WoS",$G11="Scopus"),$H11>=50),$G11="Dimensions")))),$K11,"")) | N11: sim
A12: Anderson Saldanha Bueno | B12: =IF($A12="","",IFERROR(VLOOKUP($A12,'Resumo por docente'!$A$8:$B$57,2,FALSE),"")) -> Biodiversidade, Saúde Ambiental e Conservação | C12: 2024 | D12: Extending Species-Area Relationships Into the Realm of Ecoacoustics: The Soundscape-Area Relationship | E12: https://doi.org/10.1111/ele.14529 | K12: =IF($A12="","",IF(OR($G12="WoS",$G12="Scopus"),IF($H12="","",IF($H12>=87.5,1,IF($H12>=75,0.875,IF($H12>=62.5,0.75,IF($H12>=50,0.625,IF($H12>=37.5,0.5,IF($H12>=25,0.375,IF($H12>=12.5,0.25,IF($H12>=0.01,0.125,0))))))))),IF($G12="Dimensions",IF(OR($I12="",$J12=""),"",MIN(IF($I12>=87.5,1,IF($I12>=75,0.875,IF($I12>=62.5,0.75,IF($I12>=50,0.625,IF($I12>=37.5,0.5,IF($I12>=25,0.375,IF($I12>=12.5,0.25,IF($I12>=0.01,0.125,0)))))))),IF($J12>=2,1,IF($J12>=1.5,0.875,IF($J12>=1,0.75,IF($J12>=0.75,0.625,IF($J12>=0.5,0.5,IF($J12>=0.25,0.375,IF($J12>=0.125,0.25,IF($J12>=0.01,0.125,0)))))))))),""))) | L12: =IF($A12="","",IF(AND($C12>=2021,$C12<=2026,$E12<>"",$K12>0,LOWER($N12)="sim",LOWER($O12)="sim",OR(AND($F12="Exterior",OR($G12="WoS",$G12="Scopus")),AND($F12="Brasil",OR(AND(OR($G12="WoS",$G12="Scopus"),$H12>=50),$G12="Dimensions")))),$K12,"")) | N12: sim
A13: Anderson Saldanha Bueno | B13: =IF($A13="","",IFERROR(VLOOKUP($A13,'Resumo por docente'!$A$8:$B$57,2,FALSE),"")) -> Biodiversidade, Saúde Ambiental e Conservação | C13: 2023 | D13: Number of forest fragments and understory plants exert opposite effects on multiple facets of bird diversity in eucalypt plantations | E13: https://doi.org/10.1007/s10980-023-01601-5 | K13: =IF($A13="","",IF(OR($G13="WoS",$G13="Scopus"),IF($H13="","",IF($H13>=87.5,1,IF($H13>=75,0.875,IF($H13>=62.5,0.75,IF($H13>=50,0.625,IF($H13>=37.5,0.5,IF($H13>=25,0.375,IF($H13>=12.5,0.25,IF($H13>=0.01,0.125,0))))))))),IF($G13="Dimensions",IF(OR($I13="",$J13=""),"",MIN(IF($I13>=87.5,1,IF($I13>=75,0.875,IF($I13>=62.5,0.75,IF($I13>=50,0.625,IF($I13>=37.5,0.5,IF($I13>=25,0.375,IF($I13>=12.5,0.25,IF($I13>=0.01,0.125,0)))))))),IF($J13>=2,1,IF($J13>=1.5,0.875,IF($J13>=1,0.75,IF($J13>=0.75,0.625,IF($J13>=0.5,0.5,IF($J13>=0.25,0.375,IF($J13>=0.125,0.25,IF($J13>=0.01,0.125,0)))))))))),""))) | L13: =IF($A13="","",IF(AND($C13>=2021,$C13<=2026,$E13<>"",$K13>0,LOWER($N13)="sim",LOWER($O13)="sim",OR(AND($F13="Exterior",OR($G13="WoS",$G13="Scopus")),AND($F13="Brasil",OR(AND(OR($G13="WoS",$G13="Scopus"),$H13>=50),$G13="Dimensions")))),$K13,"")) | N13: sim
A14: Anderson Saldanha Bueno | B14: =IF($A14="","",IFERROR(VLOOKUP($A14,'Resumo por docente'!$A$8:$B$57,2,FALSE),"")) -> Biodiversidade, Saúde Ambiental e Conservação | C14: 2023 | D14: Pervasive gaps in Amazonian ecological research | E14: https://doi.org/10.1016/j.cub.2023.06.077 | K14: =IF($A14="","",IF(OR($G14="WoS",$G14="Scopus"),IF($H14="","",IF($H14>=87.5,1,IF($H14>=75,0.875,IF($H14>=62.5,0.75,IF($H14>=50,0.625,IF($H14>=37.5,0.5,IF($H14>=25,0.375,IF($H14>=12.5,0.25,IF($H14>=0.01,0.125,0))))))))),IF($G14="Dimensions",IF(OR($I14="",$J14=""),"",MIN(IF($I14>=87.5,1,IF($I14>=75,0.875,IF($I14>=62.5,0.75,IF($I14>=50,0.625,IF($I14>=37.5,0.5,IF($I14>=25,0.375,IF($I14>=12.5,0.25,IF($I14>=0.01,0.125,0)))))))),IF($J14>=2,1,IF($J14>=1.5,0.875,IF($J14>=1,0.75,IF($J14>=0.75,0.625,IF($J14>=0.5,0.5,IF($J14>=0.25,0.375,IF($J14>=0.125,0.25,IF($J14>=0.01,0.125,0)))))))))),""))) | L14: =IF($A14="","",IF(AND($C14>=2021,$C14<=2026,$E14<>"",$K14>0,LOWER($N14)="sim",LOWER($O14)="sim",OR(AND($F14="Exterior",OR($G14="WoS",$G14="Scopus")),AND($F14="Brasil",OR(AND(OR($G14="WoS",$G14="Scopus"),$H14>=50),$G14="Dimensions")))),$K14,"")) | N14: sim
A15: Anderson Saldanha Bueno | B15: =IF($A15="","",IFERROR(VLOOKUP($A15,'Resumo por docente'!$A$8:$B$57,2,FALSE),"")) -> Biodiversidade, Saúde Ambiental e Conservação | C15: 2022 | D15: Assessing assemblage-wide mammal responses to different types of habitat modification in Amazonian forests | E15: https://doi.org/10.1038/s41598-022-05450-1 | K15: =IF($A15="","",IF(OR($G15="WoS",$G15="Scopus"),IF($H15="","",IF($H15>=87.5,1,IF($H15>=75,0.875,IF($H15>=62.5,0.75,IF($H15>=50,0.625,IF($H15>=37.5,0.5,IF($H15>=25,0.375,IF($H15>=12.5,0.25,IF($H15>=0.01,0.125,0))))))))),IF($G15="Dimensions",IF(OR($I15="",$J15=""),"",MIN(IF($I15>=87.5,1,IF($I15>=75,0.875,IF($I15>=62.5,0.75,IF($I15>=50,0.625,IF($I15>=37.5,0.5,IF($I15>=25,0.375,IF($I15>=12.5,0.25,IF($I15>=0.01,0.125,0)))))))),IF($J15>=2,1,IF($J15>=1.5,0.875,IF($J15>=1,0.75,IF($J15>=0.75,0.625,IF($J15>=0.5,0.5,IF($J15>=0.25,0.375,IF($J15>=0.125,0.25,IF($J15>=0.01,0.125,0)))))))))),""))) | L15: =IF($A15="","",IF(AND($C15>=2021,$C15<=2026,$E15<>"",$K15>0,LOWER($N15)="sim",LOWER($O15)="sim",OR(AND($F15="Exterior",OR($G15="WoS",$G15="Scopus")),AND($F15="Brasil",OR(AND(OR($G15="WoS",$G15="Scopus"),$H15>=50),$G15="Dimensions")))),$K15,"")) | N15: sim
